Workbook

Sheet ВидыРабот
A1: Работы
A3: вывоз навоза без прицепа
A4: вывоз навоза с прицепом 10 т
A5: вывоз навоза с прицепом 4 т
A6: разовые поручения
A7: раздача кормов
A8: почасовая работа в кормоцехе
A9: перемещение силоса
A10: опрыскивание спецтехникой
A11: опрыскивание прицепным агрегатом
A12: вывоз жижи бочка 10т
A13: вывоз жижи бочка 5т
... A141: погрузка кукуры

Sheet НеРаботал
A1: На больничном
A2: На учебе
A3: Не работал по уважительной причине
A4: Не работал по неуважительной причине
A5: Выходной

Sheet техника
B1: ООО Шахтер | I1: ООО Шахтер
A2: № | B2: ФИО | C2: Вид техники | D2: Комментарии | H2: п/п | I2: Вид техники | K2: трекер есть
A3: водители
A4: 1 | B4: Сибгатуллин Ильшат | C4: КАМАЗ | H4: 1 | I4: КАМАЗ | K4: +
A5: 2 | B5: Хакимов Алмаз | C5: КАМАЗ | H5: 2 | I5: КАМАЗ | K5: +
A6: 3 | B6: Шакиров Алмаз | C6: КАМАЗ | H6: 3 | I6: КАМАЗ | K6: +
A7: 4 | B7: Хакимуллин Алмаз | C7: КАМАЗ | H7: 4 | I7: КАМАЗ | K7: +
A8: 5 | B8: Гилязов Марат | C8: КАМАЗ | H8: 5 | I8: КАМАЗ | K8: +
A9: 6 | B9: Самигуллин Марат | C9: КАМАЗ | H9: 6 | I9: КАМАЗ | K9: +
A10: 7 | B10: Хуснутдинов Рамиль | C10: КАМАЗ | H10: 7 | I10: КАМАЗ | K10: +
A11: 8 | B11: Хазиев Данис | C11: КАМАЗ | H11: 8 | I11: КАМАЗ | K11: +
A12: 9 | B12: Зиннатуллин Ильяр | C12: ГАЗ-53/пожарный | H12: 1 | I12: ГАЗ-53 бортовой | K12: +
A13: механизаторы | H13: 2 | I13: ГАЗ-53 пожарный | K13: -
A14: 1 | B14: Гарипов Айрат | C14: МТЗ-1221 яна | H14: 3 | I14: Газ-53 бензовоз | K14: +
A15: 2 | B15: Даминов Алмаз | C15: МТЗ-1221 яна | H15: 1 | I15: МТЗ-1221 | K15: +
A16: 3 | B16: Сибгатуллин Ренат | C16: МТЗ-1221 | H16: 2 | I16: МТЗ-1221 | K16: +
A17: 4 | B17: Марданов Ильнур | C17: МТЗ-1221 | H17: 3 | I17: МТЗ-1221 | K17: +
A18: 5 | B18: Марданов Газинур | C18: МТЗ-1221 | H18: 4 | I18: МТЗ-1221 | K18: +
A19: 6 | B19: Гилязутдинов Равис | C19: МТЗ-1221 | H19: 5 | I19: МТЗ-1221 | K19: +
A20: 7 | B20: Идрисов Фанис | C20: МТЗ-1221 | H20: 6 | I20: МТЗ-1221 | K20: +
A21: 8 | B21: Бурганов Ильдус | C21: МТЗ-1221 | H21: 7 | I21: МТЗ-1221 | K21: +
A22: 9 | B22: Зиннатуллин Ильнар | C22: МТЗ-82/К-744 | H22: 8 | I22: МТЗ-1221 | K22: +
A23: 10 | B23: Гарипов Радиф | C23: МТЗ-82 яна | H23: 9 | I23: МТЗ-1221 | K23: +
A24: 11 | B24: Гарипов Ленар | C24: МТЗ-82 кун10 | H24: 1 | I24: МТЗ-82 | K24: +
A25: 12 | B25: Гилязов Фариль | C25: МТЗ-82 | H25: 2 | I25: МТЗ-82 | K25: +
... A32: 19 | B32: Сафиуллин Фидаиль | C32: К-742 | H32: 9 | I32: МТЗ-82 | K32: +
A33: 20 | B33: Сафиуллин Фердинант | H33: 10 | I33: МТЗ-82 | K33: +
A34: 21 | B34: Газимзянов Мунир | C34: Yutong | H34: 1 | I34: ДТ-75 | K34: +
A35: 22 | B35: Мухаметзянов Радик | C35: Yutong | H35: 2 | I35: К-742 | K35: +
A36: 23 | B36: Ибрагимов Ильнар | C36: Нью холланд | H36: 3 | I36: К-744 | K36: +
A37: 24 | B37: Шагиев Данис | C37: ШАМТУЙ | H37: 4 | I37: Yutong-931a | K37: +
A38: 25 | B38: Шарифуллин Рамазан | C38: JSB новый/старый | H38: 5 | I38: Yutong-931a 0058 | K38: +
A39: 26 | B39: Мухаметшин Рамиль/ | H39: 6 | I39: Нью холланд | K39: +
A40: 27 | B40: Шарифуллин Рузиль | C40: ВАЛТРА | H40: 7 | I40: Нью холланд | K40: +
A41: 28 | B41: Ибрагимов Зиннур | C41: механизатор | H41: 8 | I41: ШАМТУЙ | K41: +
A42: вахта | H42: 9 | I42: JSB новый | K42: -
A43: 1 | B43: Шайхутдинов Габдельфат | C43: УАЗ-Буханка | H43: 10 | I43: JSB старый | K43: +
A44: 2 | B44: Шарафутдинов Рустам | C44: УАЗ-Буханка | H44: 11 | I44: ВАЛТРА | K44: +
A45: слесари | H45: 12 | I45: БАРС-3000 | K45: +
A46: 1 | B46: Латыйпов Ильдус | C46: ст.слесарь | H46: 13 | I46: ХТЗ-150 | K46: +
...

Sheet 01.07.2025
B2: ООО Шахтер | E2: Памятка по цветам
B3: Дата | C3: 45839 | E3: Столбец/строка с критической для работы информацией | F3: Используется в критичной для работы программы логике, должна быть заполнена корректно
E4: Столбец с информацией для генерации отчета | F4: Используется для генерации отчета (Наличие корректной информации отвечает за полноценность информации отчета и не критично)
E5: Мультиполя | F5: Могут быть корректно обработаны в случае нескольких работ у 1 человека. (Имеет смысл указывать только желтые и оранжевые поля для вторых и последующих вхождений одного и того же ID)
A8: № | B8: ID | C8: ФИО | D8: Вид техники | E8: Комментарии | F8: Вид работы | G8: Расценка | H8: Кол-во рейсов/час/га/рулонов/тонн-км | I8: Отработано, часов | J8: Общее кол-во часов | K8: Общее кол-во дней | L8: Сумма за день | M8: Сумма за месяц | N8: Общее кол-во дней ремонта | O8: Причина отсут.на раб.месте
A9: 1 | C9: Сибгатуллин Ильшат | D9: КАМАЗ | F9: =CONCATENATE(F10," \ ",F11) -> Перемещение разных товаров с прицепом \ ремонт среднего ТС | I9: =SUM(I10:I12) -> 8 | J9: =I9 -> 8 | K9: 1 | L9: =SUM(L10:L12) -> 4056 | M9: =L9 -> 4056 | N9: 0
A10: 1 | B10: B321-4958-B09E-D1C4 | C10: Сибгатуллин Ильшат | D10: КАМАЗ | F10: Перемещение разных товаров с прицепом | G10: 2.16 | H10: 1600 | I10: 4 | J10: =J9 -> 8 | K10: =K9 -> 1 | L10: =G10*H10 -> 3456 | M10: =M9 -> 4056 | O10: {=IFERROR(_xlfn.IFS(O9="Не работал по уважительной причине","Не работал по уважительной причине",O9="На учебе","На учебе",O9="На больничном","На больничном",O9="Выходной","Выходной", O9="Не работал по неуважительной причине","Не работал по неуважительной причине"),"")}
A11: 1 | B11: B321-4958-B09E-D1C4 | C11: Сибгатуллин Ильшат | D11: КАМАЗ | F11: ремонт среднего ТС | G11: 150 | H11: 4 | I11: 4 | L11: =G11*H11 -> 600
A12: 1
A13: 2 | C13: Хакимов Алмаз | D13: КАМАЗ | F13: =CONCATENATE(F14," \ ",F15) -> Перемещение разных товаров без прицепа \ | I13: =SUM(I14:I16) -> 4 | J13: =I13 -> 4 | K13: 1 | L13: =SUM(L14:L16) -> 864 | M13: =L13 -> 864 | N13: 0
A14: 2 | B14: F81C-A5F6-75F0-A039 | C14: Хакимов Алмаз | D14: КАМАЗ | F14: Перемещение разных товаров без прицепа | G14: 2.16 | H14: 400 | I14: 4 | J14: =J13 -> 4 | K14: =K13 -> 1 | L14: =G14*H14 -> 864 | M14: =M13 -> 864 | O14: {=IFERROR(_xlfn.IFS(O13="Не работал по уважительной причине","Не работал по уважительной причине",O13="На учебе","На учебе",O13="На больничном","На больничном",O13="Выходной","Выходной", O13="Не работал по неуважительной причине","Не работал по неуважительной причине"),"")}
A15: 2
A16: 2
A17: 3 | C17: Шакиров Алмаз | D17: КАМАЗ | F17: =CONCATENATE(F18," \ ",F19) -> ремонт среднего ТС \ | I17: =SUM(I18:I20) -> 8 | J17: =I17 -> 8 | K17: 1 | L17: =SUM(L18:L20) -> 1200 | M17: =L17 -> 1200 | N17: 1
A18: 3 | B18: B132-B3D7-F67D-21D6 | C18: Шакиров Алмаз | D18: КАМАЗ 327 | F18: ремонт среднего ТС | G18: 150 | H18: 8 | I18: 8 | J18: =J17 -> 8 | K18: =K17 -> 1 | L18: =G18*H18 -> 1200 | M18: =M17 -> 1200 | O18: {=IFERROR(_xlfn.IFS(O17="Не работал по уважительной причине","Не работал по уважительной причине",O17="На учебе","На учебе",O17="На больничном","На больничном",O17="Выходной","Выходной", O17="Не работал по неуважительной причине","Не работал по неуважительной причине"),"")}
A19: 3
A20: 3
A21: 4 | C21: Хакимуллин Алмаз | D21: КАМАЗ | F21: =CONCATENATE(F22," \ ",F23) -> ремонт среднего ТС \ Перемещение разных товаров без прицепа | I21: =SUM(I22:I24) -> 8 | J21: =I21 -> 8 | K21: 1 | L21: =SUM(L22:L24) -> 3969.6 | M21: =L21 -> 3969.6 | N21: 0
A22: 4 | B22: 1EEC-A4AA-2E5F-816A | C22: Хакимуллин Алмаз | D22: КАМАЗ | F22: ремонт среднего ТС | G22: 150 | H22: 4 | I22: 5 | J22: =J21 -> 8 | K22: =K21 -> 1 | L22: =G22*H22 -> 600 | M22: =M21 -> 3969.6 | O22: {=IFERROR(_xlfn.IFS(O21="Не работал по уважительной причине","Не работал по уважительной причине",O21="На учебе","На учебе",O21="На больничном","На больничном",O21="Выходной","Выходной", O21="Не работал по неуважительной причине","Не работал по неуважительной причине"),"")}
A23: 4 | B23: 1EEC-A4AA-2E5F-816A | C23: Хакимуллин Алмаз | D23: КАМАЗ | F23: Перемещение разных товаров без прицепа | G23: 2.16 | H23: 1560 | I23: 3 | L23: =G23*H23 -> 3369.6
A24: 4
A25: 5 | C25: Гилязов Марат | D25: КАМАЗ | F25: =CONCATENATE(F26," \ ",F27) -> ремонт большого ТС \ | I25: =SUM(I26:I28) -> 8 | J25: =I25 -> 8 | K25: 1 | L25: =SUM(L26:L28) -> 1600 | M25: =L25 -> 1600 | N25: 0
A26: 5 | B26: 9B87-3AB6-19F1-3F4F | C26: Гилязов Марат | D26: Ягуар | F26: ремонт большого ТС | G26: 200 | H26: 8 | I26: 8 | J26: =J25 -> 8 | K26: =K25 -> 1 | L26: =G26*H26 -> 1600 | M26: =M25 -> 1600 | O26: {=IFERROR(_xlfn.IFS(O25="Не работал по уважительной причине","Не работал по уважительной причине",O25="На учебе","На учебе",O25="На больничном","На больничном",O25="Выходной","Выходной", O25="Не работал по неуважительной причине","Не работал по неуважительной причине"),"")}
A27: 5
A28: 5
A29: 6 | C29: Самигуллин Марат | D29: КАМАЗ | F29: =CONCATENATE(F30," \ ",F31) -> ремонт среднего ТС \ | I29: =SUM(I30:I32) -> 8 | J29: =I29 -> 8 | K29: 1 | L29: =SUM(L30:L32) -> 1200 | M29: =L29 -> 1200 | N29: 0
A30: 6 | B30: DB23-B6ED-A237-F7F2 | C30: Самигуллин Марат | D30: Камаз | F30: ремонт среднего ТС | G30: 150 | H30: 8 | I30: 8 | J30: =J29 -> 8 | K30: =K29 -> 1 | L30: =G30*I30 -> 1200 | M30: =M29 -> 1200 | O30: {=IFERROR(_xlfn.IFS(O29="Не работал по уважительной причине","Не работал по уважительной причине",O29="На учебе","На учебе",O29="На больничном","На больничном",O29="Выходной","Выходной", O29="Не работал по неуважительной причине","Не работал по неуважительной причине"),"")}
A31: 6
A32: 6
A33: 7 | C33: Хуснутдинов Рамиль | D33: КАМАЗ | F33: =CONCATENATE(F34," \ ",F35) -> Перемещение разных товаров с прицепом \ | I33: =SUM(I34:I36) -> 8 | J33: =I33 -> 8 | K33: 1 | L33: =SUM(L34:L36) -> 3456 | M33: =L33 -> 3456 | N33: 0
A34: 7 | B34: 826C-55E4-ED1D-8549 | C34: Хуснутдинов Рамиль | D34: КАМАЗ | F34: Перемещение разных товаров с прицепом | G34: 2.16 | H34: 1600 | I34: 8 | J34: =J33 -> 8 | K34: =K33 -> 1 | L34: =G34*H34 -> 3456 | M34: =M33 -> 3456 | O34: {=IFERROR(_xlfn.IFS(O33="Не работал по уважительной причине","Не работал по уважительной причине",O33="На учебе","На учебе",O33="На больничном","На больничном",O33="Выходной","Выходной", O33="Не работал по неуважительной причине","Не работал по неуважительной причине"),"")}
A35: 7
A36: 7
A37: 8 | C37: Сафиуллин Фердинант | D37: К-744 | F37: =CONCATENATE(F38," \ ",F39) -> \ | I37: =SUM(I38:I40) -> 0 | J37: =I37 -> 0 | K37: 1 | L37: =SUM(L38:L40) -> 0 | M37: =L37 -> 0 | N37: 0 | O37: Не работал по уважительной причине
A38: 8 | B38: A70E-55AE-4C30-61A5 | C38: Сафиуллин Фердинант | D38: К-744 | J38: =J37 -> 0 | K38: =K37 -> 1 | L38: =G38*I38 -> 0 | M38: =M37 -> 0 | O38: {=IFERROR(_xlfn.IFS(O37="Не работал по уважительной причине","Не работал по уважительной причине",O37="На учебе","На учебе",O37="На больничном","На больничном",O37="Выходной","Выходной", O37="Не работал по неуважительной причине","Не работал по неуважительной причине"),"")} -> Не работал по уважительной причине
A39: 8
A40: 8
A41: 9 | C41: Зиннатуллин Ильяр | D41: ГАЗ-53/пожарный | F41: =CONCATENATE(F42," \ ",F43) -> \ | I41: =SUM(I42:I44) -> 0 | J41: =I41 -> 0 | K41: 1 | L41: =SUM(L42:L44) -> 0 | M41: =L41 -> 0 | N41: 0 | O41: Не работал по уважительной причине
A42: 9 | B42: 84AC-63E7-9D34-A357 | C42: Зиннатуллин Ильяр | D42: ГАЗ-53/пожарный | J42: =J41 -> 0 | K42: =K41 -> 1 | L42: =G42*I42 -> 0 | M42: =M41 -> 0 | O42: {=IFERROR(_xlfn.IFS(O41="Не работал по уважительной причине","Не работал по уважительной причине",O41="На учебе","На учебе",O41="На больничном","На больничном",O41="Выходной","Выходной", O41="Не работал по неуважительной причине","Не работал по неуважительной причине"),"")} -> Не работал по уважительной причине
A43: 9
...

Sheet 02.07.2025
B2: ООО Шахтер | E2: Памятка по цветам
B3: Дата | C3: 45840 | E3: Столбец/строка с критической для работы информацией | F3: Используется в критичной для работы программы логике, должна быть заполнена корректно
E4: Столбец с информацией для генерации отчета | F4: Используется для генерации отчета (Наличие корректной информации отвечает за полноценность информации отчета и не критично)
E5: Мультиполя | F5: Могут быть корректно обработаны в случае нескольких работ у 1 человека. (Имеет смысл указывать только желтые и оранжевые поля для вторых и последующих вхождений одного и того же ID)
A8: № | B8: ID | C8: ФИО | D8: Вид техники | E8: Комментарии | F8: Вид работы | G8: Расценка | H8: Кол-во рейсов/час/га/рулонов/тонн-км | I8: Отработано, часов | J8: Общее кол-во часов | K8: Общее кол-во дней | L8: Сумма за день | M8: Сумма за месяц | N8: Общее кол-во дней ремонта | O8: Причина отсут.на раб.месте
A9: 1 | C9: Сибгатуллин Ильшат | D9: КАМАЗ | F9: =CONCATENATE(F10," \ ",F11," \ ",F12) -> Перемещение разных товаров с прицепом \ Ожидание во время рейса \ | I9: =SUM(I10:I12) -> 8 | J9: ='01.07.2025'!J9+I9 -> 16 | K9: =IF(I9>0,'01.07.2025'!K9+1,'01.07.2025'!K9) -> 2 | L9: =SUM(L10:L12) -> 4515.2 | M9: ='01.07.2025'!M9+L9 -> 8571.2 | N9: 0
A10: 1 | B10: B321-4958-B09E-D1C4 | C10: Сибгатуллин Ильшат | D10: КАМАЗ | F10: Перемещение разных товаров с прицепом | G10: 2.16 | H10: 1720 | I10: 4 | J10: =J9 -> 16 | K10: =K9 -> 2 | L10: =G10*H10 -> 3715.2 | M10: =M9 -> 8571.2 | O10: {=IFERROR(_xlfn.IFS(O9="Не работал по уважительной причине","Не работал по уважительной причине",O9="На учебе","На учебе",O9="На больничном","На больничном",O9="Выходной","Выходной", O9="Не работал по неуважительной причине","Не работал по неуважительной причине"),"")}
A11: 1 | B11: B321-4958-B09E-D1C4 | C11: Сибгатуллин Ильшат | D11: КАМАЗ | F11: Ожидание во время рейса | G11: 200 | H11: 4 | I11: 4 | L11: =G11*H11 -> 800
A12: 1
A13: 2 | C13: Хакимов Алмаз | D13: КАМАЗ | F13: =CONCATENATE(F14," \ ",F15," \ ",F16) -> \ \ | I13: =SUM(I14:I16) -> 0 | J13: ='01.07.2025'!J13+I13 -> 4 | K13: =IF(I13>0,'01.07.2025'!K13+1,'01.07.2025'!K13) -> 1 | L13: =SUM(L14:L16) -> 0 | M13: ='01.07.2025'!M13+L13 -> 864 | N13: 0 | O13: Не работал по уважительной причине
A14: 2 | B14: F81C-A5F6-75F0-A039 | C14: Хакимов Алмаз | D14: КАМАЗ | J14: =J13 -> 4 | K14: =K13 -> 1 | L14: =G14*H14 -> 0 | M14: =M13 -> 864 | O14: {=IFERROR(_xlfn.IFS(O13="Не работал по уважительной причине","Не работал по уважительной причине",O13="На учебе","На учебе",O13="На больничном","На больничном",O13="Выходной","Выходной", O13="Не работал по неуважительной причине","Не работал по неуважительной причине"),"")} -> Не работал по уважительной причине
A15: 2
A16: 2
A17: 3 | C17: Шакиров Алмаз | D17: КАМАЗ | F17: =CONCATENATE(F18," \ ",F19," \ ",F20) -> ремонт среднего ТС \ \ | I17: =SUM(I18:I20) -> 8 | J17: ='01.07.2025'!J17+I17 -> 16 | K17: =IF(I17>0,'01.07.2025'!K17+1,'01.07.2025'!K17) -> 2 | L17: =SUM(L18:L20) -> 1200 | M17: ='01.07.2025'!M17+L17 -> 2400 | N17: 2
A18: 3 | B18: B132-B3D7-F67D-21D6 | C18: Шакиров Алмаз | D18: КАМАЗ | F18: ремонт среднего ТС | G18: 150 | H18: 8 | I18: 8 | J18: =J17 -> 16 | K18: =K17 -> 2 | L18: =G18*H18 -> 1200 | M18: =M17 -> 2400 | O18: {=IFERROR(_xlfn.IFS(O17="Не работал по уважительной причине","Не работал по уважительной причине",O17="На учебе","На учебе",O17="На больничном","На больничном",O17="Выходной","Выходной", O17="Не работал по неуважительной причине","Не работал по неуважительной причине"),"")}
A19: 3
A20: 3
A21: 4 | C21: Хакимуллин Алмаз | D21: КАМАЗ | F21: =CONCATENATE(F22," \ ",F23," \ ",F24) -> ремонт среднего ТС \ \ | I21: =SUM(I22:I24) -> 8 | J21: ='01.07.2025'!J21+I21 -> 16 | K21: =IF(I21>0,'01.07.2025'!K21+1,'01.07.2025'!K21) -> 2 | L21: =SUM(L22:L24) -> 1200 | M21: ='01.07.2025'!M21+L21 -> 5169.6 | N21: 1
A22: 4 | B22: 1EEC-A4AA-2E5F-816A | C22: Хакимуллин Алмаз | D22: КАМАЗ | F22: ремонт среднего ТС | G22: 150 | H22: 8 | I22: 8 | J22: =J21 -> 16 | K22: =K21 -> 2 | L22: =G22*H22 -> 1200 | M22: =M21 -> 5169.6 | O22: {=IFERROR(_xlfn.IFS(O21="Не работал по уважительной причине","Не работал по уважительной причине",O21="На учебе","На учебе",O21="На больничном","На больничном",O21="Выходной","Выходной", O21="Не работал по неуважительной причине","Не работал по неуважительной причине"),"")}
A23: 4 | L23: =G23*H23 -> 0
A24: 4
A25: 5 | C25: Гилязов Марат | D25: КАМАЗ | F25: =CONCATENATE(F26," \ ",F27," \ ",F28) -> ремонт большого ТС \ \ | I25: =SUM(I26:I28) -> 8 | J25: ='01.07.2025'!J25+I25 -> 16 | K25: =IF(I25>0,'01.07.2025'!K25+1,'01.07.2025'!K25) -> 2 | L25: =SUM(L26:L28) -> 1600 | M25: ='01.07.2025'!M25+L25 -> 3200 | N25: 0
A26: 5 | B26: 9B87-3AB6-19F1-3F4F | C26: Гилязов Марат | D26: Ягуар | F26: ремонт большого ТС | G26: 200 | H26: 8 | I26: 8 | J26: =J25 -> 16 | K26: =K25 -> 2 | L26: =G26*H26 -> 1600 | M26: =M25 -> 3200 | O26: {=IFERROR(_xlfn.IFS(O25="Не работал по уважительной причине","Не работал по уважительной причине",O25="На учебе","На учебе",O25="На больничном","На больничном",O25="Выходной","Выходной", O25="Не работал по неуважительной причине","Не работал по неуважительной причине"),"")}
A27: 5
A28: 5
A29: 6 | C29: Самигуллин Марат | D29: КАМАЗ | F29: =CONCATENATE(F30," \ ",F31," \ ",F32) -> ремонт среднего ТС \ Перемещение разных товаров без прицепа \ Ожидание во время рейса | I29: =SUM(I30:I32) -> 9 | J29: ='01.07.2025'!J29+I29 -> 17 | K29: =IF(I29>0,'01.07.2025'!K29+1,'01.07.2025'!K29) -> 2 | L29: =SUM(L30:L32) -> 2296 | M29: ='01.07.2025'!M29+L29 -> 3496 | N29: 0
A30: 6 | B30: DB23-B6ED-A237-F7F2 | C30: Самигуллин Марат | D30: КАМАЗ | F30: ремонт среднего ТС | G30: 150 | H30: 4 | I30: 4 | J30: =J29 -> 17 | K30: =K29 -> 2 | L30: =G30*H30 -> 600 | M30: =M29 -> 3496 | O30: {=IFERROR(_xlfn.IFS(O29="Не работал по уважительной причине","Не работал по уважительной причине",O29="На учебе","На учебе",O29="На больничном","На больничном",O29="Выходной","Выходной", O29="Не работал по неуважительной причине","Не работал по неуважительной причине"),"")}
A31: 6 | B31: DB23-B6ED-A237-F7F2 | C31: Самигуллин Марат | D31: КАМАЗ | F31: Перемещение разных товаров без прицепа | G31: 2.16 | H31: 600 | I31: 3 | L31: =G31*H31 -> 1296
A32: 6 | B32: DB23-B6ED-A237-F7F2 | C32: Самигуллин Марат | D32: КАМАЗ | F32: Ожидание во время рейса | G32: 200 | H32: 2 | I32: 2 | L32: =G32*H32 -> 400
A33: 7 | C33: Хуснутдинов Рамиль | D33: КАМАЗ | F33: =CONCATENATE(F34," \ ",F35," \ ",F36) -> работа в зернотоке \ \ | I33: =SUM(I34:I36) -> 7 | J33: ='01.07.2025'!J33+I33 -> 15 | K33: =IF(I33>0,'01.07.2025'!K33+1,'01.07.2025'!K33) -> 2 | L33: =SUM(L34:L36) -> 1750 | M33: ='01.07.2025'!M33+L33 -> 5206 | N33: 0
A34: 7 | B34: 826C-55E4-ED1D-8549 | C34: Хуснутдинов Рамиль | D34: КАМАЗ | F34: работа в зернотоке | G34: 250 | H34: 7 | I34: 7 | J34: =J33 -> 15 | K34: =K33 -> 2 | L34: =G34*H34 -> 1750 | M34: =M33 -> 5206 | O34: {=IFERROR(_xlfn.IFS(O33="Не работал по уважительной причине","Не работал по уважительной причине",O33="На учебе","На учебе",O33="На больничном","На больничном",O33="Выходной","Выходной", O33="Не работал по неуважительной причине","Не работал по неуважительной причине"),"")}
A35: 7
A36: 7
A37: 8 | C37: Сафиуллин Фердинант | D37: К-744 | F37: =CONCATENATE(F38," \ ",F39," \ ",F40) -> \ \ | I37: =SUM(I38:I40) -> 0 | J37: ='01.07.2025'!J37+I37 -> 0 | K37: =IF(I37>0,'01.07.2025'!K37+1,'01.07.2025'!K37) -> 1 | L37: =SUM(L38:L40) -> 0 | M37: ='01.07.2025'!M37+L37 -> 0 | N37: 0 | O37: Не работал по уважительной причине
A38: 8 | B38: A70E-55AE-4C30-61A5 | C38: Сафиуллин Фердинант | D38: К-744 | J38: =J37 -> 0 | K38: =K37 -> 1 | L38: =G38*I38 -> 0 | M38: =M37 -> 0 | O38: {=IFERROR(_xlfn.IFS(O37="Не работал по уважительной причине","Не работал по уважительной причине",O37="На учебе","На учебе",O37="На больничном","На больничном",O37="Выходной","Выходной", O37="Не работал по неуважительной причине","Не работал по неуважительной причине"),"")} -> Не работал по уважительной причине
A39: 8
A40: 8
A41: 9 | C41: Зиннатуллин Ильяр | D41: ГАЗ-53/пожарный | F41: =CONCATENATE(F42," \ ",F43," \ ",F44) -> \ \ | I41: =SUM(I42:I44) -> 0 | J41: ='01.07.2025'!J41+I41 -> 0 | K41: =IF(I41>0,'01.07.2025'!K41+1,'01.07.2025'!K41) -> 1 | L41: =SUM(L42:L44) -> 0 | M41: ='01.07.2025'!M41+L41 -> 0 | N41: 0 | O41: Не работал по уважительной причине
A42: 9 | B42: 84AC-63E7-9D34-A357 | C42: Зиннатуллин Ильяр | D42: ГАЗ-53/пожарный | J42: =J41 -> 0 | K42: =K41 -> 1 | L42: =G42*I42 -> 0 | M42: =M41 -> 0 | O42: {=IFERROR(_xlfn.IFS(O41="Не работал по уважительной причине","Не работал по уважительной причине",O41="На учебе","На учебе",O41="На больничном","На больничном",O41="Выходной","Выходной", O41="Не работал по неуважительной причине","Не работал по неуважительной причине"),"")} -> Не работал по уважительной причине
A43: 9
...

Sheet 03.07.2025
B2: ООО Шахтер | E2: Памятка по цветам
B3: Дата | C3: 45841 | E3: Столбец/строка с критической для работы информацией | F3: Используется в критичной для работы программы логике, должна быть заполнена корректно
E4: Столбец с информацией для генерации отчета | F4: Используется для генерации отчета (Наличие корректной информации отвечает за полноценность информации отчета и не критично)
E5: Мультиполя | F5: Могут быть корректно обработаны в случае нескольких работ у 1 человека. (Имеет смысл указывать только желтые и оранжевые поля для вторых и последующих вхождений одного и того же ID)
A8: № | B8: ID | C8: ФИО | D8: Вид техники | E8: Комментарии | F8: Вид работы | G8: Расценка | H8: Кол-во рейсов/час/га/рулонов/тонн-км | I8: Отработано, часов | J8: Общее кол-во часов | K8: Общее кол-во дней | L8: Сумма за день | M8: Сумма за месяц | N8: Общее кол-во дней ремонта | O8: Причина отсут.на раб.месте
A9: 1 | C9: Сибгатуллин Ильшат | D9: КАМАЗ | F9: =CONCATENATE(F10," \ ",F11," \ ",F12) -> ремонт среднего ТС \ \ | I9: =SUM(I10:I12) -> 8 | J9: ='02.07.2025'!J9+I9 -> 24 | K9: =IF(I9>0,'02.07.2025'!K9+1,'02.07.2025'!K9) -> 3 | L9: =SUM(L10:L12) -> 1200 | M9: ='02.07.2025'!M9+L9 -> 9771.2 | N9: 0
A10: 1 | B10: B321-4958-B09E-D1C4 | C10: Сибгатуллин Ильшат | D10: КАМАЗ | F10: ремонт среднего ТС | G10: 150 | H10: 8 | I10: 8 | J10: =J9 -> 24 | K10: =K9 -> 3 | L10: =G10*H10 -> 1200 | M10: =M9 -> 9771.2 | O10: {=IFERROR(_xlfn.IFS(O9="Не работал по уважительной причине","Не работал по уважительной причине",O9="На учебе","На учебе",O9="На больничном","На больничном",O9="Выходной","Выходной", O9="Не работал по неуважительной причине","Не работал по неуважительной причине"),"")}
A11: 1 | L11: =G11*H11 -> 0
A12: 1
A13: 2 | C13: Хакимов Алмаз | D13: КАМАЗ | F13: =CONCATENATE(F14," \ ",F15," \ ",F16) -> ремонт среднего ТС \ \ | I13: =SUM(I14:I16) -> 0 | J13: ='02.07.2025'!J13+I13 -> 4 | K13: =IF(I13>0,'02.07.2025'!K13+1,'02.07.2025'!K13) -> 1 | L13: =SUM(L14:L16) -> 0 | M13: ='02.07.2025'!M13+L13 -> 864 | N13: 0 | O13: Не работал по уважительной причине
A14: 2 | B14: F81C-A5F6-75F0-A039 | C14: Хакимов Алмаз | D14: КАМАЗ | F14: ремонт среднего ТС | J14: =J13 -> 4 | K14: =K13 -> 1 | L14: =G14*H14 -> 0 | M14: =M13 -> 864 | O14: {=IFERROR(_xlfn.IFS(O13="Не работал по уважительной причине","Не работал по уважительной причине",O13="На учебе","На учебе",O13="На больничном","На больничном",O13="Выходной","Выходной", O13="Не работал по неуважительной причине","Не работал по неуважительной причине"),"")} -> Не работал по уважительной причине
A15: 2
A16: 2
A17: 3 | C17: Шакиров Алмаз | D17: КАМАЗ | F17: =CONCATENATE(F18," \ ",F19," \ ",F20) -> ремонт среднего ТС \ \ | I17: =SUM(I18:I20) -> 8 | J17: ='02.07.2025'!J17+I17 -> 24 | K17: =IF(I17>0,'02.07.2025'!K17+1,'02.07.2025'!K17) -> 3 | L17: =SUM(L18:L20) -> 1200 | M17: ='02.07.2025'!M17+L17 -> 3600 | N17: 2
A18: 3 | B18: B132-B3D7-F67D-21D6 | C18: Шакиров Алмаз | D18: КАМАЗ | F18: ремонт среднего ТС | G18: 150 | H18: 8 | I18: 8 | J18: =J17 -> 24 | K18: =K17 -> 3 | L18: =G18*H18 -> 1200 | M18: =M17 -> 3600 | O18: {=IFERROR(_xlfn.IFS(O17="Не работал по уважительной причине","Не работал по уважительной причине",O17="На учебе","На учебе",O17="На больничном","На больничном",O17="Выходной","Выходной", O17="Не работал по неуважительной причине","Не работал по неуважительной причине"),"")}
A19: 3
A20: 3
A21: 4 | C21: Хакимуллин Алмаз | D21: КАМАЗ | F21: =CONCATENATE(F22," \ ",F23," \ ",F24) -> ремонт среднего ТС \ \ | I21: =SUM(I22:I24) -> 8 | J21: ='02.07.2025'!J21+I21 -> 24 | K21: =IF(I21>0,'02.07.2025'!K21+1,'02.07.2025'!K21) -> 3 | L21: =SUM(L22:L24) -> 1200 | M21: ='02.07.2025'!M21+L21 -> 6369.6 | N21: 1
A22: 4 | B22: 1EEC-A4AA-2E5F-816A | C22: Хакимуллин Алмаз | D22: КАМАЗ | F22: ремонт среднего ТС | G22: 150 | H22: 8 | I22: 8 | J22: =J21 -> 24 | K22: =K21 -> 3 | L22: =G22*H22 -> 1200 | M22: =M21 -> 6369.6 | O22: {=IFERROR(_xlfn.IFS(O21="Не работал по уважительной причине","Не работал по уважительной причине",O21="На учебе","На учебе",O21="На больничном","На больничном",O21="Выходной","Выходной", O21="Не работал по неуважительной причине","Не работал по неуважительной причине"),"")}
A23: 4 | L23: =G23*H23 -> 0
A24: 4
A25: 5 | C25: Гилязов Марат | D25: КАМАЗ | F25: =CONCATENATE(F26," \ ",F27," \ ",F28) -> ремонт большого ТС \ \ | I25: =SUM(I26:I28) -> 8 | J25: ='02.07.2025'!J25+I25 -> 24 | K25: =IF(I25>0,'02.07.2025'!K25+1,'02.07.2025'!K25) -> 3 | L25: =SUM(L26:L28) -> 1600 | M25: ='02.07.2025'!M25+L25 -> 4800 | N25: 0
A26: 5 | B26: 9B87-3AB6-19F1-3F4F | C26: Гилязов Марат | D26: Ягуар | F26: ремонт большого ТС | G26: 200 | H26: 8 | I26: 8 | J26: =J25 -> 24 | K26: =K25 -> 3 | L26: =G26*H26 -> 1600 | M26: =M25 -> 4800 | O26: {=IFERROR(_xlfn.IFS(O25="Не работал по уважительной причине","Не работал по уважительной причине",O25="На учебе","На учебе",O25="На больничном","На больничном",O25="Выходной","Выходной", O25="Не работал по неуважительной причине","Не работал по неуважительной причине"),"")}
A27: 5
A28: 5
A29: 6 | C29: Самигуллин Марат | D29: КАМАЗ | F29: =CONCATENATE(F30," \ ",F31," \ ",F32) -> ремонт среднего ТС \ Перемещение разных товаров с прицепом \ | I29: =SUM(I30:I32) -> 9 | J29: ='02.07.2025'!J29+I29 -> 26 | K29: =IF(I29>0,'02.07.2025'!K29+1,'02.07.2025'!K29) -> 3 | L29: =SUM(L30:L32) -> 1848 | M29: ='02.07.2025'!M29+L29 -> 5344 | N29: 0
A30: 6 | B30: DB23-B6ED-A237-F7F2 | C30: Самигуллин Марат | D30: КАМАЗ | F30: ремонт среднего ТС | G30: 150 | H30: 8 | I30: 8 | J30: =J29 -> 26 | K30: =K29 -> 3 | L30: =G30*H30 -> 1200 | M30: =M29 -> 5344 | O30: {=IFERROR(_xlfn.IFS(O29="Не работал по уважительной причине","Не работал по уважительной причине",O29="На учебе","На учебе",O29="На больничном","На больничном",O29="Выходной","Выходной", O29="Не работал по неуважительной причине","Не работал по неуважительной причине"),"")}
A31: 6 | B31: DB23-B6ED-A237-F7F2 | C31: Самигуллин Марат | D31: КАМАЗ | F31: Перемещение разных товаров с прицепом | G31: 2.16 | H31: 300 | I31: 1 | L31: =G31*H31 -> 648
A32: 6 | L32: =G32*H32 -> 0
A33: 7 | C33: Хуснутдинов Рамиль | D33: КАМАЗ | F33: =CONCATENATE(F34," \ ",F35," \ ",F36) -> ремонт среднего ТС \ \ | I33: =SUM(I34:I36) -> 8 | J33: ='02.07.2025'!J33+I33 -> 23 | K33: =IF(I33>0,'02.07.2025'!K33+1,'02.07.2025'!K33) -> 3 | L33: =SUM(L34:L36) -> 1200 | M33: ='02.07.2025'!M33+L33 -> 6406 | N33: 0
A34: 7 | B34: 826C-55E4-ED1D-8549 | C34: Хуснутдинов Рамиль | D34: КАМАЗ | F34: ремонт среднего ТС | G34: 150 | H34: 8 | I34: 8 | J34: =J33 -> 23 | K34: =K33 -> 3 | L34: =G34*H34 -> 1200 | M34: =M33 -> 6406 | O34: {=IFERROR(_xlfn.IFS(O33="Не работал по уважительной причине","Не работал по уважительной причине",O33="На учебе","На учебе",O33="На больничном","На больничном",O33="Выходной","Выходной", O33="Не работал по неуважительной причине","Не работал по неуважительной причине"),"")}
A35: 7
A36: 7
A37: 8 | C37: Сафиуллин Фердинант | D37: К-744 | F37: =CONCATENATE(F38," \ ",F39," \ ",F40) -> \ \ | I37: =SUM(I38:I40) -> 0 | J37: ='02.07.2025'!J37+I37 -> 0 | K37: =IF(I37>0,'02.07.2025'!K37+1,'02.07.2025'!K37) -> 1 | L37: =SUM(L38:L40) -> 0 | M37: ='02.07.2025'!M37+L37 -> 0 | N37: 0 | O37: Не работал по уважительной причине
A38: 8 | B38: A70E-55AE-4C30-61A5 | C38: Сафиуллин Фердинант | D38: К-744 | J38: =J37 -> 0 | K38: =K37 -> 1 | L38: =G38*I38 -> 0 | M38: =M37 -> 0 | O38: {=IFERROR(_xlfn.IFS(O37="Не работал по уважительной причине","Не работал по уважительной причине",O37="На учебе","На учебе",O37="На больничном","На больничном",O37="Выходной","Выходной", O37="Не работал по неуважительной причине","Не работал по неуважительной причине"),"")} -> Не работал по уважительной причине
A39: 8
A40: 8
A41: 9 | C41: Зиннатуллин Ильяр | D41: ГАЗ-53/пожарный | F41: =CONCATENATE(F42," \ ",F43," \ ",F44) -> \ \ | I41: =SUM(I42:I44) -> 0 | J41: ='02.07.2025'!J41+I41 -> 0 | K41: =IF(I41>0,'02.07.2025'!K41+1,'02.07.2025'!K41) -> 1 | L41: =SUM(L42:L44) -> 0 | M41: ='02.07.2025'!M41+L41 -> 0 | N41: 0 | O41: Не работал по уважительной причине
A42: 9 | B42: 84AC-63E7-9D34-A357 | C42: Зиннатуллин Ильяр | D42: ГАЗ-53/пожарный | J42: =J41 -> 0 | K42: =K41 -> 1 | L42: =G42*I42 -> 0 | M42: =M41 -> 0 | O42: {=IFERROR(_xlfn.IFS(O41="Не работал по уважительной причине","Не работал по уважительной причине",O41="На учебе","На учебе",O41="На больничном","На больничном",O41="Выходной","Выходной", O41="Не работал по неуважительной причине","Не работал по неуважительной причине"),"")} -> Не работал по уважительной причине
A43: 9
...

Sheet 04.07.2025
B2: ООО Шахтер | E2: Памятка по цветам
B3: Дата | C3: 45842 | E3: Столбец/строка с критической для работы информацией | F3: Используется в критичной для работы программы логике, должна быть заполнена корректно
E4: Столбец с информацией для генерации отчета | F4: Используется для генерации отчета (Наличие корректной информации отвечает за полноценность информации отчета и не критично)
E5: Мультиполя | F5: Могут быть корректно обработаны в случае нескольких работ у 1 человека. (Имеет смысл указывать только желтые и оранжевые поля для вторых и последующих вхождений одного и того же ID)
A8: № | B8: ID | C8: ФИО | D8: Вид техники | E8: Комментарии | F8: Вид работы | G8: Расценка | H8: Кол-во рейсов/час/га/рулонов/тонн-км | I8: Отработано, часов | J8: Общее кол-во часов | K8: Общее кол-во дней | L8: Сумма за день | M8: Сумма за месяц | N8: Общее кол-во дней ремонта | O8: Причина отсут.на раб.месте
A9: 1 | C9: Сибгатуллин Ильшат | D9: КАМАЗ | F9: =CONCATENATE(F10," \ ",F11," \ ",F12) -> \ \ | I9: =SUM(I10:I12) -> 0 | J9: ='03.07.2025'!J9+I9 -> 24 | K9: =IF(I9>0,'03.07.2025'!K9+1,'03.07.2025'!K9) -> 3 | L9: =SUM(L10:L12) -> 0 | M9: ='03.07.2025'!M9+L9 -> 9771.2 | N9: 0 | O9: Не работал по уважительной причине
A10: 1 | B10: B321-4958-B09E-D1C4 | C10: Сибгатуллин Ильшат | D10: КАМАЗ | J10: =J9 -> 24 | K10: =K9 -> 3 | L10: =G10*H10 -> 0 | M10: =M9 -> 9771.2 | O10: {=IFERROR(_xlfn.IFS(O9="Не работал по уважительной причине","Не работал по уважительной причине",O9="На учебе","На учебе",O9="На больничном","На больничном",O9="Выходной","Выходной", O9="Не работал по неуважительной причине","Не работал по неуважительной причине"),"")} -> Не работал по уважительной причине
A11: 1 | L11: =G11*H11 -> 0
A12: 1
A13: 2 | C13: Хакимов Алмаз | D13: КАМАЗ | F13: =CONCATENATE(F14," \ ",F15," \ ",F16) -> ремонт среднего ТС \ \ | I13: =SUM(I14:I16) -> 8 | J13: ='03.07.2025'!J13+I13 -> 12 | K13: =IF(I13>0,'03.07.2025'!K13+1,'03.07.2025'!K13) -> 2 | L13: =SUM(L14:L16) -> 1200 | M13: ='03.07.2025'!M13+L13 -> 2064 | N13: 0
A14: 2 | B14: F81C-A5F6-75F0-A039 | C14: Хакимов Алмаз | D14: КАМАЗ | F14: ремонт среднего ТС | G14: 150 | H14: 8 | I14: 8 | J14: =J13 -> 12 | K14: =K13 -> 2 | L14: =G14*H14 -> 1200 | M14: =M13 -> 2064 | O14: {=IFERROR(_xlfn.IFS(O13="Не работал по уважительной причине","Не работал по уважительной причине",O13="На учебе","На учебе",O13="На больничном","На больничном",O13="Выходной","Выходной", O13="Не работал по неуважительной причине","Не работал по неуважительной причине"),"")}
A15: 2
A16: 2
A17: 3 | C17: Шакиров Алмаз | D17: КАМАЗ | F17: =CONCATENATE(F18," \ ",F19," \ ",F20) -> ремонт среднего ТС \ \ | I17: =SUM(I18:I20) -> 4 | J17: ='03.07.2025'!J17+I17 -> 28 | K17: =IF(I17>0,'03.07.2025'!K17+1,'03.07.2025'!K17) -> 4 | L17: =SUM(L18:L20) -> 600 | M17: ='03.07.2025'!M17+L17 -> 4200 | N17: 2
A18: 3 | B18: B132-B3D7-F67D-21D6 | C18: Шакиров Алмаз | D18: КАМАЗ | F18: ремонт среднего ТС | G18: 150 | H18: 4 | I18: 4 | J18: =J17 -> 28 | K18: =K17 -> 4 | L18: =G18*H18 -> 600 | M18: =M17 -> 4200 | O18: {=IFERROR(_xlfn.IFS(O17="Не работал по уважительной причине","Не работал по уважительной причине",O17="На учебе","На учебе",O17="На больничном","На больничном",O17="Выходной","Выходной", O17="Не работал по неуважительной причине","Не работал по неуважительной причине"),"")}
A19: 3
A20: 3
A21: 4 | C21: Хакимуллин Алмаз | D21: КАМАЗ | F21: =CONCATENATE(F22," \ ",F23," \ ",F24) -> ремонт среднего ТС \ \ | I21: =SUM(I22:I24) -> 8 | J21: ='03.07.2025'!J21+I21 -> 32 | K21: =IF(I21>0,'03.07.2025'!K21+1,'03.07.2025'!K21) -> 4 | L21: =SUM(L22:L24) -> 1200 | M21: ='03.07.2025'!M21+L21 -> 7569.6 | N21: 1
A22: 4 | B22: 1EEC-A4AA-2E5F-816A | C22: Хакимуллин Алмаз | D22: КАМАЗ | F22: ремонт среднего ТС | G22: 150 | H22: 8 | I22: 8 | J22: =J21 -> 32 | K22: =K21 -> 4 | L22: =G22*H22 -> 1200 | M22: =M21 -> 7569.6 | O22: {=IFERROR(_xlfn.IFS(O21="Не работал по уважительной причине","Не работал по уважительной причине",O21="На учебе","На учебе",O21="На больничном","На больничном",O21="Выходной","Выходной", O21="Не работал по неуважительной причине","Не работал по неуважительной причине"),"")}
A23: 4 | L23: =G23*H23 -> 0
A24: 4
A25: 5 | C25: Гилязов Марат | D25: КАМАЗ | F25: =CONCATENATE(F26," \ ",F27," \ ",F28) -> ремонт большого ТС \ \ | I25: =SUM(I26:I28) -> 8 | J25: ='03.07.2025'!J25+I25 -> 32 | K25: =IF(I25>0,'03.07.2025'!K25+1,'03.07.2025'!K25) -> 4 | L25: =SUM(L26:L28) -> 1600 | M25: ='03.07.2025'!M25+L25 -> 6400 | N25: 0
A26: 5 | B26: 9B87-3AB6-19F1-3F4F | C26: Гилязов Марат | D26: Ягуар | F26: ремонт большого ТС | G26: 200 | H26: 8 | I26: 8 | J26: =J25 -> 32 | K26: =K25 -> 4 | L26: =G26*H26 -> 1600 | M26: =M25 -> 6400 | O26: {=IFERROR(_xlfn.IFS(O25="Не работал по уважительной причине","Не работал по уважительной причине",O25="На учебе","На учебе",O25="На больничном","На больничном",O25="Выходной","Выходной", O25="Не работал по неуважительной причине","Не работал по неуважительной причине"),"")}
A27: 5
A28: 5
A29: 6 | C29: Самигуллин Марат | D29: КАМАЗ | F29: =CONCATENATE(F30," \ ",F31," \ ",F32) -> ремонт среднего ТС \ \ | I29: =SUM(I30:I32) -> 8 | J29: ='03.07.2025'!J29+I29 -> 34 | K29: =IF(I29>0,'03.07.2025'!K29+1,'03.07.2025'!K29) -> 4 | L29: =SUM(L30:L32) -> 1200 | M29: ='03.07.2025'!M29+L29 -> 6544 | N29: 0
A30: 6 | B30: DB23-B6ED-A237-F7F2 | C30: Самигуллин Марат | D30: КАМАЗ | F30: ремонт среднего ТС | G30: 150 | H30: 8 | I30: 8 | J30: =J29 -> 34 | K30: =K29 -> 4 | L30: =G30*H30 -> 1200 | M30: =M29 -> 6544 | O30: {=IFERROR(_xlfn.IFS(O29="Не работал по уважительной причине","Не работал по уважительной причине",O29="На учебе","На учебе",O29="На больничном","На больничном",O29="Выходной","Выходной", O29="Не работал по неуважительной причине","Не работал по неуважительной причине"),"")}
A31: 6 | L31: =G31*H31 -> 0
A32: 6 | L32: =G32*H32 -> 0
A33: 7 | C33: Хуснутдинов Рамиль | D33: КАМАЗ | F33: =CONCATENATE(F34," \ ",F35," \ ",F36) -> ремонт среднего ТС \ \ | I33: =SUM(I34:I36) -> 8 | J33: ='03.07.2025'!J33+I33 -> 31 | K33: =IF(I33>0,'03.07.2025'!K33+1,'03.07.2025'!K33) -> 4 | L33: =SUM(L34:L36) -> 1200 | M33: ='03.07.2025'!M33+L33 -> 7606 | N33: 0
A34: 7 | B34: 826C-55E4-ED1D-8549 | C34: Хуснутдинов Рамиль | D34: КАМАЗ | F34: ремонт среднего ТС | G34: 150 | H34: 8 | I34: 8 | J34: =J33 -> 31 | K34: =K33 -> 4 | L34: =G34*H34 -> 1200 | M34: =M33 -> 7606 | O34: {=IFERROR(_xlfn.IFS(O33="Не работал по уважительной причине","Не работал по уважительной причине",O33="На учебе","На учебе",O33="На больничном","На больничном",O33="Выходной","Выходной", O33="Не работал по неуважительной причине","Не работал по неуважительной причине"),"")}
A35: 7
A36: 7
A37: 8 | C37: Сафиуллин Фердинант | D37: К-744 | F37: =CONCATENATE(F38," \ ",F39," \ ",F40) -> \ \ | I37: =SUM(I38:I40) -> 0 | J37: ='03.07.2025'!J37+I37 -> 0 | K37: =IF(I37>0,'03.07.2025'!K37+1,'03.07.2025'!K37) -> 1 | L37: =SUM(L38:L40) -> 0 | M37: ='03.07.2025'!M37+L37 -> 0 | N37: 0 | O37: Не работал по уважительной причине
A38: 8 | B38: A70E-55AE-4C30-61A5 | C38: Сафиуллин Фердинант | D38: К-744 | J38: =J37 -> 0 | K38: =K37 -> 1 | L38: =G38*I38 -> 0 | M38: =M37 -> 0 | O38: {=IFERROR(_xlfn.IFS(O37="Не работал по уважительной причине","Не работал по уважительной причине",O37="На учебе","На учебе",O37="На больничном","На больничном",O37="Выходной","Выходной", O37="Не работал по неуважительной причине","Не работал по неуважительной причине"),"")} -> Не работал по уважительной причине
A39: 8
A40: 8
A41: 9 | C41: Зиннатуллин Ильяр | D41: ГАЗ-53/пожарный | F41: =CONCATENATE(F42," \ ",F43," \ ",F44) -> вахта пожарная \ \ | I41: =SUM(I42:I44) -> 4 | J41: ='03.07.2025'!J41+I41 -> 4 | K41: =IF(I41>0,'03.07.2025'!K41+1,'03.07.2025'!K41) -> 2 | L41: =SUM(L42:L44) -> 864 | M41: ='03.07.2025'!M41+L41 -> 864 | N41: 0
A42: 9 | B42: 84AC-63E7-9D34-A357 | C42: Зиннатуллин Ильяр | D42: ГАЗ-53/пожарный | F42: вахта пожарная | G42: 216 | H42: 4 | I42: 4 | J42: =J41 -> 4 | K42: =K41 -> 2 | L42: =G42*I42 -> 864 | M42: =M41 -> 864 | O42: {=IFERROR(_xlfn.IFS(O41="Не работал по уважительной причине","Не работал по уважительной причине",O41="На учебе","На учебе",O41="На больничном","На больничном",O41="Выходной","Выходной", O41="Не работал по неуважительной причине","Не работал по неуважительной причине"),"")}
A43: 9
...

Sheet 05.07.2025
B2: ООО Шахтер | E2: Памятка по цветам
B3: Дата | C3: 45843 | E3: Столбец/строка с критической для работы информацией | F3: Используется в критичной для работы программы логике, должна быть заполнена корректно
E4: Столбец с информацией для генерации отчета | F4: Используется для генерации отчета (Наличие корректной информации отвечает за полноценность информации отчета и не критично)
E5: Мультиполя | F5: Могут быть корректно обработаны в случае нескольких работ у 1 человека. (Имеет смысл указывать только желтые и оранжевые поля для вторых и последующих вхождений одного и того же ID)
A8: № | B8: ID | C8: ФИО | D8: Вид техники | E8: Комментарии | F8: Вид работы | G8: Расценка | H8: Кол-во рейсов/час/га/рулонов/тонн-км | I8: Отработано, часов | J8: Общее кол-во часов | K8: Общее кол-во дней | L8: Сумма за день | M8: Сумма за месяц | N8: Общее кол-во дней ремонта | O8: Причина отсут.на раб.месте
A9: 1 | C9: Сибгатуллин Ильшат | D9: КАМАЗ | F9: =CONCATENATE(F10," \ ",F11," \ ",F12) -> вывоз навоза без прицепа \ ремонт среднего ТС \ | I9: =SUM(I10:I12) -> 5 | J9: ='04.07.2025'!J9+I9 -> 29 | K9: =IF(I9>0,'04.07.2025'!K9+1,'04.07.2025'!K9) -> 4 | L9: =SUM(L10:L12) -> 1746 | M9: ='04.07.2025'!M9+L9 -> 11517.2 | N9: 0
A10: 1 | B10: B321-4958-B09E-D1C4 | C10: Сибгатуллин Ильшат | D10: КАМАЗ | F10: вывоз навоза без прицепа | G10: 25.92 | H10: 50 | I10: 2 | J10: =J9 -> 29 | K10: =K9 -> 4 | L10: =G10*H10 -> 1296 | M10: =M9 -> 11517.2 | O10: {=IFERROR(_xlfn.IFS(O9="Не работал по уважительной причине","Не работал по уважительной причине",O9="На учебе","На учебе",O9="На больничном","На больничном",O9="Выходной","Выходной", O9="Не работал по неуважительной причине","Не работал по неуважительной причине"),"")}
A11: 1 | B11: B321-4958-B09E-D1C4 | C11: Сибгатуллин Ильшат | D11: КАМАЗ | F11: ремонт среднего ТС | G11: 150 | H11: 3 | I11: 3 | L11: =G11*H11 -> 450
A12: 1
A13: 2 | C13: Хакимов Алмаз | D13: КАМАЗ | F13: =CONCATENATE(F14," \ ",F15," \ ",F16) -> ремонт среднего ТС \ вывоз навоза без прицепа \ | I13: =SUM(I14:I16) -> 11 | J13: ='04.07.2025'!J13+I13 -> 23 | K13: =IF(I13>0,'04.07.2025'!K13+1,'04.07.2025'!K13) -> 3 | L13: =SUM(L14:L16) -> 2005.2 | M13: ='04.07.2025'!M13+L13 -> 4069.2 | N13: 0
A14: 2 | B14: F81C-A5F6-75F0-A039 | C14: Хакимов Алмаз | D14: КАМАЗ | F14: ремонт среднего ТС | G14: 150 | H14: 3 | I14: 8 | J14: =J13 -> 23 | K14: =K13 -> 3 | L14: =G14*H14 -> 450 | M14: =M13 -> 4069.2 | O14: {=IFERROR(_xlfn.IFS(O13="Не работал по уважительной причине","Не работал по уважительной причине",O13="На учебе","На учебе",O13="На больничном","На больничном",O13="Выходной","Выходной", O13="Не работал по неуважительной причине","Не работал по неуважительной причине"),"")}
A15: 2 | B15: F81C-A5F6-75F0-A039 | C15: Хакимов Алмаз | D15: КАМАЗ | F15: вывоз навоза без прицепа | G15: 25.92 | H15: 60 | I15: 3 | L15: =G15*H15 -> 1555.2
A16: 2
A17: 3 | C17: Шакиров Алмаз | D17: КАМАЗ | F17: =CONCATENATE(F18," \ ",F19," \ ",F20) -> \ \ | I17: =SUM(I18:I20) -> 0 | J17: ='04.07.2025'!J17+I17 -> 28 | K17: =IF(I17>0,'04.07.2025'!K17+1,'04.07.2025'!K17) -> 4 | L17: =SUM(L18:L20) -> 0 | M17: ='04.07.2025'!M17+L17 -> 4200 | N17: 2 | O17: Не работал по уважительной причине
A18: 3 | B18: B132-B3D7-F67D-21D6 | C18: Шакиров Алмаз | D18: КАМАЗ | J18: =J17 -> 28 | K18: =K17 -> 4 | L18: =G18*H18 -> 0 | M18: =M17 -> 4200 | O18: {=IFERROR(_xlfn.IFS(O17="Не работал по уважительной причине","Не работал по уважительной причине",O17="На учебе","На учебе",O17="На больничном","На больничном",O17="Выходной","Выходной", O17="Не работал по неуважительной причине","Не работал по неуважительной причине"),"")} -> Не работал по уважительной причине
A19: 3
A20: 3
A21: 4 | C21: Хакимуллин Алмаз | D21: КАМАЗ | F21: =CONCATENATE(F22," \ ",F23," \ ",F24) -> ремонт среднего ТС \ вывоз навоза без прицепа \ | I21: =SUM(I22:I24) -> 5 | J21: ='04.07.2025'!J21+I21 -> 37 | K21: =IF(I21>0,'04.07.2025'!K21+1,'04.07.2025'!K21) -> 5 | L21: =SUM(L22:L24) -> 1746 | M21: ='04.07.2025'!M21+L21 -> 9315.6 | N21: 1
A22: 4 | B22: 1EEC-A4AA-2E5F-816A | C22: Хакимуллин Алмаз | D22: КАМАЗ | F22: ремонт среднего ТС | G22: 150 | H22: 3 | I22: 3 | J22: =J21 -> 37 | K22: =K21 -> 5 | L22: =G22*H22 -> 450 | M22: =M21 -> 9315.6 | O22: {=IFERROR(_xlfn.IFS(O21="Не работал по уважительной причине","Не работал по уважительной причине",O21="На учебе","На учебе",O21="На больничном","На больничном",O21="Выходной","Выходной", O21="Не работал по неуважительной причине","Не работал по неуважительной причине"),"")}
A23: 4 | B23: 1EEC-A4AA-2E5F-816A | C23: Хакимуллин Алмаз | D23: КАМАЗ | F23: вывоз навоза без прицепа | G23: 25.92 | H23: 50 | I23: 2 | L23: =G23*H23 -> 1296
A24: 4
A25: 5 | C25: Гилязов Марат | D25: КАМАЗ | F25: =CONCATENATE(F26," \ ",F27," \ ",F28) -> ремонт большого ТС \ \ | I25: =SUM(I26:I28) -> 8 | J25: ='04.07.2025'!J25+I25 -> 40 | K25: =IF(I25>0,'04.07.2025'!K25+1,'04.07.2025'!K25) -> 5 | L25: =SUM(L26:L28) -> 1600 | M25: ='04.07.2025'!M25+L25 -> 8000 | N25: 0
A26: 5 | B26: 9B87-3AB6-19F1-3F4F | C26: Гилязов Марат | D26: Ягуар | F26: ремонт большого ТС | G26: 200 | H26: 8 | I26: 8 | J26: =J25 -> 40 | K26: =K25 -> 5 | L26: =G26*H26 -> 1600 | M26: =M25 -> 8000 | O26: {=IFERROR(_xlfn.IFS(O25="Не работал по уважительной причине","Не работал по уважительной причине",O25="На учебе","На учебе",O25="На больничном","На больничном",O25="Выходной","Выходной", O25="Не работал по неуважительной причине","Не работал по неуважительной причине"),"")}
A27: 5
A28: 5
A29: 6 | C29: Самигуллин Марат | D29: КАМАЗ | F29: =CONCATENATE(F30," \ ",F31," \ ",F32) -> ремонт среднего ТС \ вывоз навоза без прицепа \ | I29: =SUM(I30:I32) -> 7 | J29: ='04.07.2025'!J29+I29 -> 41 | K29: =IF(I29>0,'04.07.2025'!K29+1,'04.07.2025'!K29) -> 5 | L29: =SUM(L30:L32) -> 2523.6 | M29: ='04.07.2025'!M29+L29 -> 9067.6 | N29: 0
A30: 6 | B30: DB23-B6ED-A237-F7F2 | C30: Самигуллин Марат | D30: КАМАЗ | F30: ремонт среднего ТС | G30: 150 | H30: 3 | I30: 3 | J30: =J29 -> 41 | K30: =K29 -> 5 | L30: =G30*H30 -> 450 | M30: =M29 -> 9067.6 | O30: {=IFERROR(_xlfn.IFS(O29="Не работал по уважительной причине","Не работал по уважительной причине",O29="На учебе","На учебе",O29="На больничном","На больничном",O29="Выходной","Выходной", O29="Не работал по неуважительной причине","Не работал по неуважительной причине"),"")}
A31: 6 | B31: DB23-B6ED-A237-F7F2 | C31: Самигуллин Марат | D31: КАМАЗ | F31: вывоз навоза без прицепа | G31: 25.92 | H31: 80 | I31: 4 | L31: =G31*H31 -> 2073.6
A32: 6 | L32: =G32*H32 -> 0
A33: 7 | C33: Хуснутдинов Рамиль | D33: КАМАЗ | F33: =CONCATENATE(F34," \ ",F35," \ ",F36) -> ремонт среднего ТС \ вывоз навоза без прицепа \ | I33: =SUM(I34:I36) -> 4 | J33: ='04.07.2025'!J33+I33 -> 35 | K33: =IF(I33>0,'04.07.2025'!K33+1,'04.07.2025'!K33) -> 5 | L33: =SUM(L34:L36) -> 1486.8 | M33: ='04.07.2025'!M33+L33 -> 9092.8 | N33: 0
A34: 7 | B34: 826C-55E4-ED1D-8549 | C34: Хуснутдинов Рамиль | D34: КАМАЗ | F34: ремонт среднего ТС | G34: 150 | H34: 3 | I34: 3 | J34: =J33 -> 35 | K34: =K33 -> 5 | L34: =G34*H34 -> 450 | M34: =M33 -> 9092.8 | O34: {=IFERROR(_xlfn.IFS(O33="Не работал по уважительной причине","Не работал по уважительной причине",O33="На учебе","На учебе",O33="На больничном","На больничном",O33="Выходной","Выходной", O33="Не работал по неуважительной причине","Не работал по неуважительной причине"),"")}
A35: 7 | B35: 826C-55E4-ED1D-8549 | C35: Хуснутдинов Рамиль | D35: КАМАЗ | F35: вывоз навоза без прицепа | G35: 25.92 | H35: 40 | I35: 1 | L35: =G35*H35 -> 1036.8
A36: 7
A37: 8 | C37: Сафиуллин Фердинант | D37: К-744 | F37: =CONCATENATE(F38," \ ",F39," \ ",F40) -> \ \ | I37: =SUM(I38:I40) -> 0 | J37: ='04.07.2025'!J37+I37 -> 0 | K37: =IF(I37>0,'04.07.2025'!K37+1,'04.07.2025'!K37) -> 1 | L37: =SUM(L38:L40) -> 0 | M37: ='04.07.2025'!M37+L37 -> 0 | N37: 0 | O37: Не работал по уважительной причине
A38: 8 | B38: A70E-55AE-4C30-61A5 | C38: Сафиуллин Фердинант | D38: К-744 | J38: =J37 -> 0 | K38: =K37 -> 1 | L38: =G38*I38 -> 0 | M38: =M37 -> 0 | O38: {=IFERROR(_xlfn.IFS(O37="Не работал по уважительной причине","Не работал по уважительной причине",O37="На учебе","На учебе",O37="На больничном","На больничном",O37="Выходной","Выходной", O37="Не работал по неуважительной причине","Не работал по неуважительной причине"),"")} -> Не работал по уважительной причине
A39: 8
A40: 8
A41: 9 | C41: Зиннатуллин Ильяр | D41: ГАЗ-53/пожарный | F41: =CONCATENATE(F42," \ ",F43," \ ",F44) -> \ \ | I41: =SUM(I42:I44) -> 0 | J41: ='04.07.2025'!J41+I41 -> 4 | K41: =IF(I41>0,'04.07.2025'!K41+1,'04.07.2025'!K41) -> 2 | L41: =SUM(L42:L44) -> 0 | M41: ='04.07.2025'!M41+L41 -> 864 | N41: 0 | O41: Не работал по уважительной причине
A42: 9 | B42: 84AC-63E7-9D34-A357 | C42: Зиннатуллин Ильяр | D42: ГАЗ-53/пожарный | J42: =J41 -> 4 | K42: =K41 -> 2 | L42: =G42*I42 -> 0 | M42: =M41 -> 864 | O42: {=IFERROR(_xlfn.IFS(O41="Не работал по уважительной причине","Не работал по уважительной причине",O41="На учебе","На учебе",O41="На больничном","На больничном",O41="Выходной","Выходной", O41="Не работал по неуважительной причине","Не работал по неуважительной причине"),"")} -> Не работал по уважительной причине
A43: 9
...

Sheet 06.07.2025
B2: ООО Шахтер | E2: Памятка по цветам
B3: Дата | C3: 45844 | E3: Столбец/строка с критической для работы информацией | F3: Используется в критичной для работы программы логике, должна быть заполнена корректно
E4: Столбец с информацией для генерации отчета | F4: Используется для генерации отчета (Наличие корректной информации отвечает за полноценность информации отчета и не критично)
E5: Мультиполя | F5: Могут быть корректно обработаны в случае нескольких работ у 1 человека. (Имеет смысл указывать только желтые и оранжевые поля для вторых и последующих вхождений одного и того же ID)
A8: № | B8: ID | C8: ФИО | D8: Вид техники | E8: Комментарии | F8: Вид работы | G8: Расценка | H8: Кол-во рейсов/час/га/рулонов/тонн-км | I8: Отработано, часов | J8: Общее кол-во часов | K8: Общее кол-во дней | L8: Сумма за день | M8: Сумма за месяц | N8: Общее кол-во дней ремонта | O8: Причина отсут.на раб.месте
A9: 1 | C9: Сибгатуллин Ильшат | D9: КАМАЗ | F9: =CONCATENATE(F10," \ ",F11," \ ",F12) -> вывоз навоза без прицепа \ \ | I9: =SUM(I10:I12) -> 7 | J9: ='05.07.2025'!J9+I9 -> 36 | K9: =IF(I9>0,'05.07.2025'!K9+1,'05.07.2025'!K9) -> 5 | L9: =SUM(L10:L12) -> 8812.8 | M9: ='05.07.2025'!M9+L9 -> 20330 | N9: 0
A10: 1 | B10: B321-4958-B09E-D1C4 | C10: Сибгатуллин Ильшат | D10: КАМАЗ | F10: вывоз навоза без прицепа | G10: 51.84 | H10: 170 | I10: 7 | J10: =J9 -> 36 | K10: =K9 -> 5 | L10: =G10*H10 -> 8812.8 | M10: =M9 -> 20330 | O10: {=IFERROR(_xlfn.IFS(O9="Не работал по уважительной причине","Не работал по уважительной причине",O9="На учебе","На учебе",O9="На больничном","На больничном",O9="Выходной","Выходной", O9="Не работал по неуважительной причине","Не работал по неуважительной причине"),"")}
A11: 1 | L11: =G11*H11 -> 0
A12: 1
A13: 2 | C13: Хакимов Алмаз | D13: КАМАЗ | F13: =CONCATENATE(F14," \ ",F15," \ ",F16) -> ремонт среднего ТС \ вывоз навоза без прицепа \ | I13: =SUM(I14:I16) -> 7 | J13: ='05.07.2025'!J13+I13 -> 30 | K13: =IF(I13>0,'05.07.2025'!K13+1,'05.07.2025'!K13) -> 4 | L13: =SUM(L14:L16) -> 6820.8 | M13: ='05.07.2025'!M13+L13 -> 10890 | N13: 0
A14: 2 | B14: F81C-A5F6-75F0-A039 | C14: Хакимов Алмаз | D14: КАМАЗ | F14: ремонт среднего ТС | G14: 300 | H14: 2 | I14: 2 | J14: =J13 -> 30 | K14: =K13 -> 4 | L14: =G14*H14 -> 600 | M14: =M13 -> 10890 | O14: {=IFERROR(_xlfn.IFS(O13="Не работал по уважительной причине","Не работал по уважительной причине",O13="На учебе","На учебе",O13="На больничном","На больничном",O13="Выходной","Выходной", O13="Не работал по неуважительной причине","Не работал по неуважительной причине"),"")}
A15: 2 | B15: F81C-A5F6-75F0-A039 | C15: Хакимов Алмаз | D15: КАМАЗ | F15: вывоз навоза без прицепа | G15: 51.84 | H15: 120 | I15: 5 | L15: =G15*H15 -> 6220.8
A16: 2
A17: 3 | C17: Шакиров Алмаз | D17: КАМАЗ | F17: =CONCATENATE(F18," \ ",F19," \ ",F20) -> \ \ | I17: =SUM(I18:I20) -> 0 | J17: ='05.07.2025'!J17+I17 -> 28 | K17: =IF(I17>0,'05.07.2025'!K17+1,'05.07.2025'!K17) -> 4 | L17: =SUM(L18:L20) -> 0 | M17: ='05.07.2025'!M17+L17 -> 4200 | N17: 2 | O17: Не работал по уважительной причине
A18: 3 | B18: B132-B3D7-F67D-21D6 | C18: Шакиров Алмаз | D18: КАМАЗ | J18: =J17 -> 28 | K18: =K17 -> 4 | L18: =G18*H18 -> 0 | M18: =M17 -> 4200 | O18: {=IFERROR(_xlfn.IFS(O17="Не работал по уважительной причине","Не работал по уважительной причине",O17="На учебе","На учебе",O17="На больничном","На больничном",O17="Выходной","Выходной", O17="Не работал по неуважительной причине","Не работал по неуважительной причине"),"")} -> Не работал по уважительной причине
A19: 3
A20: 3
A21: 4 | C21: Хакимуллин Алмаз | D21: КАМАЗ | F21: =CONCATENATE(F22," \ ",F23," \ ",F24) -> ремонт среднего ТС \ вывоз навоза без прицепа \ | I21: =SUM(I22:I24) -> 6 | J21: ='05.07.2025'!J21+I21 -> 43 | K21: =IF(I21>0,'05.07.2025'!K21+1,'05.07.2025'!K21) -> 6 | L21: =SUM(L22:L24) -> 7339.2 | M21: ='05.07.2025'!M21+L21 -> 16654.8 | N21: 1
A22: 4 | B22: 1EEC-A4AA-2E5F-816A | C22: Хакимуллин Алмаз | D22: КАМАЗ | F22: ремонт среднего ТС | G22: 300 | H22: 2 | I22: 2 | J22: =J21 -> 43 | K22: =K21 -> 6 | L22: =G22*H22 -> 600 | M22: =M21 -> 16654.8 | O22: {=IFERROR(_xlfn.IFS(O21="Не работал по уважительной причине","Не работал по уважительной причине",O21="На учебе","На учебе",O21="На больничном","На больничном",O21="Выходной","Выходной", O21="Не работал по неуважительной причине","Не работал по неуважительной причине"),"")}
A23: 4 | B23: 1EEC-A4AA-2E5F-816A | C23: Хакимуллин Алмаз | D23: КАМАЗ | F23: вывоз навоза без прицепа | G23: 51.84 | H23: 130 | I23: 4 | L23: =G23*H23 -> 6739.2
A24: 4
A25: 5 | C25: Гилязов Марат | D25: КАМАЗ | F25: =CONCATENATE(F26," \ ",F27," \ ",F28) -> ремонт большого ТС \ \ | I25: =SUM(I26:I28) -> 8 | J25: ='05.07.2025'!J25+I25 -> 48 | K25: =IF(I25>0,'05.07.2025'!K25+1,'05.07.2025'!K25) -> 6 | L25: =SUM(L26:L28) -> 3200 | M25: ='05.07.2025'!M25+L25 -> 11200 | N25: 0
A26: 5 | B26: 9B87-3AB6-19F1-3F4F | C26: Гилязов Марат | D26: Ягуар | F26: ремонт большого ТС | G26: 400 | H26: 8 | I26: 8 | J26: =J25 -> 48 | K26: =K25 -> 6 | L26: =G26*H26 -> 3200 | M26: =M25 -> 11200 | O26: {=IFERROR(_xlfn.IFS(O25="Не работал по уважительной причине","Не работал по уважительной причине",O25="На учебе","На учебе",O25="На больничном","На больничном",O25="Выходной","Выходной", O25="Не работал по неуважительной причине","Не работал по неуважительной причине"),"")}
A27: 5
A28: 5
A29: 6 | C29: Самигуллин Марат | D29: КАМАЗ | F29: =CONCATENATE(F30," \ ",F31," \ ",F32) -> вывоз навоза без прицепа \ \ | I29: =SUM(I30:I32) -> 5 | J29: ='05.07.2025'!J29+I29 -> 46 | K29: =IF(I29>0,'05.07.2025'!K29+1,'05.07.2025'!K29) -> 6 | L29: =SUM(L30:L32) -> 7776 | M29: ='05.07.2025'!M29+L29 -> 16843.6 | N29: 0
A30: 6 | B30: DB23-B6ED-A237-F7F2 | C30: Самигуллин Марат | D30: КАМАЗ | F30: вывоз навоза без прицепа | G30: 51.84 | H30: 150 | I30: 5 | J30: =J29 -> 46 | K30: =K29 -> 6 | L30: =G30*H30 -> 7776 | M30: =M29 -> 16843.6 | O30: {=IFERROR(_xlfn.IFS(O29="Не работал по уважительной причине","Не работал по уважительной причине",O29="На учебе","На учебе",O29="На больничном","На больничном",O29="Выходной","Выходной", O29="Не работал по неуважительной причине","Не работал по неуважительной причине"),"")}
A31: 6 | L31: =G31*H31 -> 0
A32: 6 | L32: =G32*H32 -> 0
A33: 7 | C33: Хуснутдинов Рамиль | D33: КАМАЗ | F33: =CONCATENATE(F34," \ ",F35," \ ",F36) -> вывоз навоза без прицепа \ \ | I33: =SUM(I34:I36) -> 7 | J33: ='05.07.2025'!J33+I33 -> 42 | K33: =IF(I33>0,'05.07.2025'!K33+1,'05.07.2025'!K33) -> 6 | L33: =SUM(L34:L36) -> 7257.6 | M33: ='05.07.2025'!M33+L33 -> 16350.4 | N33: 0
A34: 7 | B34: 826C-55E4-ED1D-8549 | C34: Хуснутдинов Рамиль | D34: КАМАЗ | F34: вывоз навоза без прицепа | G34: 51.84 | H34: 140 | I34: 7 | J34: =J33 -> 42 | K34: =K33 -> 6 | L34: =G34*H34 -> 7257.6 | M34: =M33 -> 16350.4 | O34: {=IFERROR(_xlfn.IFS(O33="Не работал по уважительной причине","Не работал по уважительной причине",O33="На учебе","На учебе",O33="На больничном","На больничном",O33="Выходной","Выходной", O33="Не работал по неуважительной причине","Не работал по неуважительной причине"),"")}
A35: 7 | L35: =G35*H35 -> 0
A36: 7
A37: 8 | C37: Сафиуллин Фердинант | D37: К-744 | F37: =CONCATENATE(F38," \ ",F39," \ ",F40) -> \ \ | I37: =SUM(I38:I40) -> 0 | J37: ='05.07.2025'!J37+I37 -> 0 | K37: =IF(I37>0,'05.07.2025'!K37+1,'05.07.2025'!K37) -> 1 | L37: =SUM(L38:L40) -> 0 | M37: ='05.07.2025'!M37+L37 -> 0 | N37: 0 | O37: Не работал по уважительной причине
A38: 8 | B38: A70E-55AE-4C30-61A5 | C38: Сафиуллин Фердинант | D38: К-744 | J38: =J37 -> 0 | K38: =K37 -> 1 | L38: =G38*I38 -> 0 | M38: =M37 -> 0 | O38: {=IFERROR(_xlfn.IFS(O37="Не работал по уважительной причине","Не работал по уважительной причине",O37="На учебе","На учебе",O37="На больничном","На больничном",O37="Выходной","Выходной", O37="Не работал по неуважительной причине","Не работал по неуважительной причине"),"")} -> Не работал по уважительной причине
A39: 8
A40: 8
A41: 9 | C41: Зиннатуллин Ильяр | D41: ГАЗ-53/пожарный | F41: =CONCATENATE(F42," \ ",F43," \ ",F44) -> вахта пожарная \ Выход пожарной машины \ | I41: =SUM(I42:I44) -> 8.3 | J41: ='05.07.2025'!J41+I41 -> 12.3 | K41: =IF(I41>0,'05.07.2025'!K41+1,'05.07.2025'!K41) -> 3 | L41: =SUM(L42:L44) -> 3789.6 | M41: ='05.07.2025'!M41+L41 -> 4653.6 | N41: 0
A42: 9 | B42: 84AC-63E7-9D34-A357 | C42: Зиннатуллин Ильяр | D42: ГАЗ-53/пожарный | F42: вахта пожарная | G42: 432 | H42: 5.3 | I42: 5.3 | J42: =J41 -> 12.3 | K42: =K41 -> 3 | L42: =G42*I42 -> 2289.6 | M42: =M41 -> 4653.6 | O42: {=IFERROR(_xlfn.IFS(O41="Не работал по уважительной причине","Не работал по уважительной причине",O41="На учебе","На учебе",O41="На больничном","На больничном",O41="Выходной","Выходной", O41="Не работал по неуважительной причине","Не работал по неуважительной причине"),"")}
A43: 9 | B43: 84AC-63E7-9D34-A357 | C43: Зиннатуллин Ильяр | D43: ГАЗ-53/пожарный | F43: Выход пожарной машины | G43: 500 | H43: 3 | I43: 3 | L43: =G43*I43 -> 1500
...

Sheet 07.07.2025
B2: ООО Шахтер | E2: Памятка по цветам
B3: Дата | C3: 45845 | E3: Столбец/строка с критической для работы информацией | F3: Используется в критичной для работы программы логике, должна быть заполнена корректно
E4: Столбец с информацией для генерации отчета | F4: Используется для генерации отчета (Наличие корректной информации отвечает за полноценность информации отчета и не критично)
E5: Мультиполя | F5: Могут быть корректно обработаны в случае нескольких работ у 1 человека. (Имеет смысл указывать только желтые и оранжевые поля для вторых и последующих вхождений одного и того же ID)
A8: № | B8: ID | C8: ФИО | D8: Вид техники | E8: Комментарии | F8: Вид работы | G8: Расценка | H8: Кол-во рейсов/час/га/рулонов/тонн-км | I8: Отработано, часов | J8: Общее кол-во часов | K8: Общее кол-во дней | L8: Сумма за день | M8: Сумма за месяц | N8: Общее кол-во дней ремонта | O8: Причина отсут.на раб.месте
A9: 1 | C9: Сибгатуллин Ильшат | D9: КАМАЗ | F9: =CONCATENATE(F10," \ ",F11," \ ",F12) -> вывоз навоза без прицепа \ \ | I9: =SUM(I10:I12) -> 9 | J9: ='06.07.2025'!J9+I9 -> 45 | K9: =IF(I9>0,'06.07.2025'!K9+1,'06.07.2025'!K9) -> 6 | L9: =SUM(L10:L12) -> 4147.2 | M9: ='06.07.2025'!M9+L9 -> 24477.2 | N9: 0
A10: 1 | B10: B321-4958-B09E-D1C4 | C10: Сибгатуллин Ильшат | D10: КАМАЗ | F10: вывоз навоза без прицепа | G10: 25.92 | H10: 160 | I10: 9 | J10: =J9 -> 45 | K10: =K9 -> 6 | L10: =G10*H10 -> 4147.2 | M10: =M9 -> 24477.2 | O10: {=IFERROR(_xlfn.IFS(O9="Не работал по уважительной причине","Не работал по уважительной причине",O9="На учебе","На учебе",O9="На больничном","На больничном",O9="Выходной","Выходной", O9="Не работал по неуважительной причине","Не работал по неуважительной причине"),"")}
A11: 1 | L11: =G11*H11 -> 0
A12: 1
A13: 2 | C13: Хакимов Алмаз | D13: КАМАЗ | F13: =CONCATENATE(F14," \ ",F15," \ ",F16) -> Перемещение разных товаров с прицепом \ \ | I13: =SUM(I14:I16) -> 8 | J13: ='06.07.2025'!J13+I13 -> 38 | K13: =IF(I13>0,'06.07.2025'!K13+1,'06.07.2025'!K13) -> 5 | L13: =SUM(L14:L16) -> 8208 | M13: ='06.07.2025'!M13+L13 -> 19098 | N13: 0
A14: 2 | B14: F81C-A5F6-75F0-A039 | C14: Хакимов Алмаз | D14: КАМАЗ | F14: Перемещение разных товаров с прицепом | G14: 2.16 | H14: 3800 | I14: 8 | J14: =J13 -> 38 | K14: =K13 -> 5 | L14: =G14*H14 -> 8208 | M14: =M13 -> 19098 | O14: {=IFERROR(_xlfn.IFS(O13="Не работал по уважительной причине","Не работал по уважительной причине",O13="На учебе","На учебе",O13="На больничном","На больничном",O13="Выходной","Выходной", O13="Не работал по неуважительной причине","Не работал по неуважительной причине"),"")}
A15: 2 | L15: =G15*H15 -> 0
A16: 2
A17: 3 | C17: Шакиров Алмаз | D17: КАМАЗ | F17: =CONCATENATE(F18," \ ",F19," \ ",F20) -> \ \ | I17: =SUM(I18:I20) -> 0 | J17: ='06.07.2025'!J17+I17 -> 28 | K17: =IF(I17>0,'06.07.2025'!K17+1,'06.07.2025'!K17) -> 4 | L17: =SUM(L18:L20) -> 0 | M17: ='06.07.2025'!M17+L17 -> 4200 | N17: 2 | O17: Не работал по уважительной причине
A18: 3 | B18: B132-B3D7-F67D-21D6 | C18: Шакиров Алмаз | D18: КАМАЗ | J18: =J17 -> 28 | K18: =K17 -> 4 | L18: =G18*H18 -> 0 | M18: =M17 -> 4200 | O18: {=IFERROR(_xlfn.IFS(O17="Не работал по уважительной причине","Не работал по уважительной причине",O17="На учебе","На учебе",O17="На больничном","На больничном",O17="Выходной","Выходной", O17="Не работал по неуважительной причине","Не работал по неуважительной причине"),"")} -> Не работал по уважительной причине
A19: 3
A20: 3
A21: 4 | C21: Хакимуллин Алмаз | D21: КАМАЗ | F21: =CONCATENATE(F22," \ ",F23," \ ",F24) -> Перемещение разных товаров с прицепом \ Перемещение разных товаров с прицепом \ | I21: =SUM(I22:I24) -> 10 | J21: ='06.07.2025'!J21+I21 -> 53 | K21: =IF(I21>0,'06.07.2025'!K21+1,'06.07.2025'!K21) -> 7 | L21: =SUM(L22:L24) -> 9504 | M21: ='06.07.2025'!M21+L21 -> 26158.8 | N21: 1
A22: 4 | B22: 1EEC-A4AA-2E5F-816A | C22: Хакимуллин Алмаз | D22: КАМАЗ | F22: Перемещение разных товаров с прицепом | G22: 2.16 | H22: 3800 | I22: 8 | J22: =J21 -> 53 | K22: =K21 -> 7 | L22: =G22*H22 -> 8208 | M22: =M21 -> 26158.8 | O22: {=IFERROR(_xlfn.IFS(O21="Не работал по уважительной причине","Не работал по уважительной причине",O21="На учебе","На учебе",O21="На больничном","На больничном",O21="Выходной","Выходной", O21="Не работал по неуважительной причине","Не работал по неуважительной причине"),"")}
A23: 4 | B23: 1EEC-A4AA-2E5F-816A | C23: Хакимуллин Алмаз | D23: КАМАЗ | F23: Перемещение разных товаров с прицепом | G23: 2.16 | H23: 600 | I23: 2 | L23: =G23*H23 -> 1296
A24: 4
A25: 5 | C25: Гилязов Марат | D25: КАМАЗ | F25: =CONCATENATE(F26," \ ",F27," \ ",F28) -> ремонт большого ТС \ \ | I25: =SUM(I26:I28) -> 8 | J25: ='06.07.2025'!J25+I25 -> 56 | K25: =IF(I25>0,'06.07.2025'!K25+1,'06.07.2025'!K25) -> 7 | L25: =SUM(L26:L28) -> 1600 | M25: ='06.07.2025'!M25+L25 -> 12800 | N25: 0
